[2022-08-21 20:52:32,212] {logging_mixin.py:109} WARNING - /home/ubuntu/anaconda3/lib/python3.9/site-packages/airflow/models/dagrun.py:418 SAWarning: TypeDecorator UtcDateTime(timezone=True) will not produce a cache key because the ``cache_ok`` attribute is not set to True.  This can have significant performance implications including some performance degradations in comparison to prior SQLAlchemy versions.  Set this attribute to True if this type object's state is safe to use in a cache key, or False to disable this warning. (Background on this error at: https://sqlalche.me/e/14/cprf)
[2022-08-21 20:52:32,219] {taskinstance.py:1035} INFO - Dependencies all met for <TaskInstance: dynamic_pricing.send_query scheduled__2022-08-20T00:00:00+00:00 [queued]>
[2022-08-21 20:52:32,230] {taskinstance.py:1035} INFO - Dependencies all met for <TaskInstance: dynamic_pricing.send_query scheduled__2022-08-20T00:00:00+00:00 [queued]>
[2022-08-21 20:52:32,230] {taskinstance.py:1241} INFO - 
--------------------------------------------------------------------------------
[2022-08-21 20:52:32,230] {taskinstance.py:1242} INFO - Starting attempt 3 of 4
[2022-08-21 20:52:32,230] {taskinstance.py:1243} INFO - 
--------------------------------------------------------------------------------
[2022-08-21 20:52:32,244] {taskinstance.py:1262} INFO - Executing <Task(PythonOperator): send_query> on 2022-08-20 00:00:00+00:00
[2022-08-21 20:52:32,246] {standard_task_runner.py:52} INFO - Started process 90736 to run task
[2022-08-21 20:52:32,249] {standard_task_runner.py:76} INFO - Running: ['airflow', 'tasks', 'run', 'dynamic_pricing', 'send_query', 'scheduled__2022-08-20T00:00:00+00:00', '--job-id', '93', '--raw', '--subdir', 'DAGS_FOLDER/dynamic_pricing.py', '--cfg-path', '/tmp/tmpqnrihktl', '--error-file', '/tmp/tmp95sb0nvv']
[2022-08-21 20:52:32,250] {standard_task_runner.py:77} INFO - Job 93: Subtask send_query
[2022-08-21 20:52:32,277] {logging_mixin.py:109} INFO - Running <TaskInstance: dynamic_pricing.send_query scheduled__2022-08-20T00:00:00+00:00 [running]> on host ip-172-31-41-223.ap-northeast-2.compute.internal
[2022-08-21 20:52:32,299] {logging_mixin.py:109} WARNING - /home/ubuntu/anaconda3/lib/python3.9/site-packages/airflow/models/xcom.py:322 SAWarning: TypeDecorator UtcDateTime(timezone=True) will not produce a cache key because the ``cache_ok`` attribute is not set to True.  This can have significant performance implications including some performance degradations in comparison to prior SQLAlchemy versions.  Set this attribute to True if this type object's state is safe to use in a cache key, or False to disable this warning. (Background on this error at: https://sqlalche.me/e/14/cprf)
[2022-08-21 20:52:32,306] {logging_mixin.py:109} WARNING - /home/ubuntu/anaconda3/lib/python3.9/site-packages/airflow/models/renderedtifields.py:126 SAWarning: TypeDecorator UtcDateTime(timezone=True) will not produce a cache key because the ``cache_ok`` attribute is not set to True.  This can have significant performance implications including some performance degradations in comparison to prior SQLAlchemy versions.  Set this attribute to True if this type object's state is safe to use in a cache key, or False to disable this warning. (Background on this error at: https://sqlalche.me/e/14/cprf)
[2022-08-21 20:52:32,311] {logging_mixin.py:109} WARNING - /home/ubuntu/anaconda3/lib/python3.9/site-packages/airflow/models/renderedtifields.py:162 SAWarning: Coercing Subquery object into a select() for use in IN(); please pass a select() construct explicitly
[2022-08-21 20:52:32,314] {logging_mixin.py:109} WARNING - /home/ubuntu/anaconda3/lib/python3.9/site-packages/airflow/models/renderedtifields.py:159 SAWarning: TypeDecorator UtcDateTime(timezone=True) will not produce a cache key because the ``cache_ok`` attribute is not set to True.  This can have significant performance implications including some performance degradations in comparison to prior SQLAlchemy versions.  Set this attribute to True if this type object's state is safe to use in a cache key, or False to disable this warning. (Background on this error at: https://sqlalche.me/e/14/cprf)
[2022-08-21 20:52:32,316] {taskinstance.py:1412} INFO - Exporting the following env vars:
AIRFLOW_CTX_DAG_OWNER=yb
AIRFLOW_CTX_DAG_ID=dynamic_pricing
AIRFLOW_CTX_TASK_ID=send_query
AIRFLOW_CTX_EXECUTION_DATE=2022-08-20T00:00:00+00:00
AIRFLOW_CTX_DAG_RUN_ID=scheduled__2022-08-20T00:00:00+00:00
[2022-08-21 20:52:32,318] {taskinstance.py:1686} ERROR - Task failed with exception
Traceback (most recent call last):
  File "/home/ubuntu/anaconda3/lib/python3.9/site-packages/airflow/models/taskinstance.py", line 1324, in _run_raw_task
    self._execute_task_with_callbacks(context)
  File "/home/ubuntu/anaconda3/lib/python3.9/site-packages/airflow/models/taskinstance.py", line 1443, in _execute_task_with_callbacks
    result = self._execute_task(context, self.task)
  File "/home/ubuntu/anaconda3/lib/python3.9/site-packages/airflow/models/taskinstance.py", line 1499, in _execute_task
    result = execute_callable(context=context)
  File "/home/ubuntu/anaconda3/lib/python3.9/site-packages/airflow/operators/python.py", line 151, in execute
    return_value = self.execute_callable()
  File "/home/ubuntu/anaconda3/lib/python3.9/site-packages/airflow/operators/python.py", line 162, in execute_callable
    return self.python_callable(*self.op_args, **self.op_kwargs)
  File "/home/ubuntu/airflow/dags/dynamic_pricing.py", line 12, in send_query
    response = requests.get(url)
  File "/home/ubuntu/anaconda3/lib/python3.9/site-packages/requests/api.py", line 75, in get
    return request('get', url, params=params, **kwargs)
  File "/home/ubuntu/anaconda3/lib/python3.9/site-packages/requests/api.py", line 61, in request
    return session.request(method=method, url=url, **kwargs)
  File "/home/ubuntu/anaconda3/lib/python3.9/site-packages/requests/sessions.py", line 529, in request
    resp = self.send(prep, **send_kwargs)
  File "/home/ubuntu/anaconda3/lib/python3.9/site-packages/requests/sessions.py", line 639, in send
    adapter = self.get_adapter(url=request.url)
  File "/home/ubuntu/anaconda3/lib/python3.9/site-packages/requests/sessions.py", line 732, in get_adapter
    raise InvalidSchema("No connection adapters were found for {!r}".format(url))
requests.exceptions.InvalidSchema: No connection adapters were found for '3.37.92.138:8001/dynamic_pricing/update'
[2022-08-21 20:52:32,321] {taskinstance.py:1270} INFO - Marking task as UP_FOR_RETRY. dag_id=dynamic_pricing, task_id=send_query, execution_date=20220820T000000, start_date=20220821T205232, end_date=20220821T205232
[2022-08-21 20:52:32,332] {standard_task_runner.py:88} ERROR - Failed to execute job 93 for task send_query
Traceback (most recent call last):
  File "/home/ubuntu/anaconda3/lib/python3.9/site-packages/airflow/task/task_runner/standard_task_runner.py", line 85, in _start_by_fork
    args.func(args, dag=self.dag)
  File "/home/ubuntu/anaconda3/lib/python3.9/site-packages/airflow/cli/cli_parser.py", line 48, in command
    return func(*args, **kwargs)
  File "/home/ubuntu/anaconda3/lib/python3.9/site-packages/airflow/utils/cli.py", line 92, in wrapper
    return f(*args, **kwargs)
  File "/home/ubuntu/anaconda3/lib/python3.9/site-packages/airflow/cli/commands/task_command.py", line 292, in task_run
    _run_task_by_selected_method(args, dag, ti)
  File "/home/ubuntu/anaconda3/lib/python3.9/site-packages/airflow/cli/commands/task_command.py", line 107, in _run_task_by_selected_method
    _run_raw_task(args, ti)
  File "/home/ubuntu/anaconda3/lib/python3.9/site-packages/airflow/cli/commands/task_command.py", line 180, in _run_raw_task
    ti._run_raw_task(
  File "/home/ubuntu/anaconda3/lib/python3.9/site-packages/airflow/utils/session.py", line 70, in wrapper
    return func(*args, session=session, **kwargs)
  File "/home/ubuntu/anaconda3/lib/python3.9/site-packages/airflow/models/taskinstance.py", line 1324, in _run_raw_task
    self._execute_task_with_callbacks(context)
  File "/home/ubuntu/anaconda3/lib/python3.9/site-packages/airflow/models/taskinstance.py", line 1443, in _execute_task_with_callbacks
    result = self._execute_task(context, self.task)
  File "/home/ubuntu/anaconda3/lib/python3.9/site-packages/airflow/models/taskinstance.py", line 1499, in _execute_task
    result = execute_callable(context=context)
  File "/home/ubuntu/anaconda3/lib/python3.9/site-packages/airflow/operators/python.py", line 151, in execute
    return_value = self.execute_callable()
  File "/home/ubuntu/anaconda3/lib/python3.9/site-packages/airflow/operators/python.py", line 162, in execute_callable
    return self.python_callable(*self.op_args, **self.op_kwargs)
  File "/home/ubuntu/airflow/dags/dynamic_pricing.py", line 12, in send_query
    response = requests.get(url)
  File "/home/ubuntu/anaconda3/lib/python3.9/site-packages/requests/api.py", line 75, in get
    return request('get', url, params=params, **kwargs)
  File "/home/ubuntu/anaconda3/lib/python3.9/site-packages/requests/api.py", line 61, in request
    return session.request(method=method, url=url, **kwargs)
  File "/home/ubuntu/anaconda3/lib/python3.9/site-packages/requests/sessions.py", line 529, in request
    resp = self.send(prep, **send_kwargs)
  File "/home/ubuntu/anaconda3/lib/python3.9/site-packages/requests/sessions.py", line 639, in send
    adapter = self.get_adapter(url=request.url)
  File "/home/ubuntu/anaconda3/lib/python3.9/site-packages/requests/sessions.py", line 732, in get_adapter
    raise InvalidSchema("No connection adapters were found for {!r}".format(url))
requests.exceptions.InvalidSchema: No connection adapters were found for '3.37.92.138:8001/dynamic_pricing/update'
[2022-08-21 20:52:32,341] {local_task_job.py:154} INFO - Task exited with return code 1
[2022-08-21 20:52:32,371] {local_task_job.py:264} INFO - 0 downstream tasks scheduled from follow-on schedule check
[2022-08-21 20:52:32,372] {logging_mixin.py:109} WARNING - /home/ubuntu/anaconda3/lib/python3.9/site-packages/airflow/models/dag.py:1069 SADeprecationWarning: Query.value() is deprecated and will be removed in a future release.  Please use Query.with_entities() in combination with Query.scalar() (deprecated since: 1.4)
[2022-08-21 20:52:32,373] {logging_mixin.py:109} WARNING - /home/ubuntu/anaconda3/lib/python3.9/site-packages/airflow/models/dag.py:1069 SADeprecationWarning: Query.values() is deprecated and will be removed in a future release.  Please use Query.with_entities() (deprecated since: 1.4)
